Workbook
Name Slicer_hr: #N/A
Name Slicer_hum: #N/A
Name Slicer_Humid_Cat: #N/A
Name Slicer_Temp_Category: #N/A
Name Slicer_Temp_Category1: #N/A
Name Slicer_Temp_Category2: #N/A
Name Slicer_Time_of_day: #N/A
Name Slicer_Time_of_day1: #N/A
Name Slicer_Weather_Situation: #N/A
Name Slicer_Windspeed_category: #N/A

Sheet Dataset_1
A1: Instant | B1: Date | C1: Season | D1: yr | E1: mnth | F1: hr | G1: time of day | H1: holiday | I1: weekday | J1: Weather_Situation | K1: Weather | L1: Column1 | M1: Temperature
A2: 1 | B2: 40544 | C2: 1 | D2: 0 | E2: 1 | F2: 0 | H2: FALSE | I2: 6 | J2: 1 | M2: 0.24
A3: 2 | B3: 40544 | C3: 1 | D3: 0 | E3: 1 | F3: 1 | H3: FALSE | I3: 6 | J3: 1 | M3: 0.22
A4: 3 | B4: 40544 | C4: 1 | D4: 0 | E4: 1 | F4: 2 | H4: FALSE | I4: 6 | J4: 1 | M4: 0.22
A5: 4 | B5: 40544 | C5: 1 | D5: 0 | E5: 1 | F5: 3 | H5: FALSE | I5: 6 | J5: 1 | M5: 0.24
A6: 5 | B6: 40544 | C6: 1 | D6: 0 | E6: 1 | F6: 4 | H6: FALSE | I6: 6 | J6: 1 | M6: 0.24
A7: 6 | B7: 40544 | C7: 1 | D7: 0 | E7: 1 | F7: 5 | H7: FALSE | I7: 6 | J7: 2 | M7: 0.24
A8: 7 | B8: 40544 | C8: 1 | D8: 0 | E8: 1 | F8: 6 | H8: FALSE | I8: 6 | J8: 1 | M8: 0.22
A9: 8 | B9: 40544 | C9: 1 | D9: 0 | E9: 1 | F9: 7 | H9: FALSE | I9: 6 | J9: 1 | M9: 0.2
A10: 9 | B10: 40544 | C10: 1 | D10: 0 | E10: 1 | F10: 8 | H10: FALSE | I10: 6 | J10: 1 | M10: 0.24
A11: 10 | B11: 40544 | C11: 1 | D11: 0 | E11: 1 | F11: 9 | H11: FALSE | I11: 6 | J11: 1 | M11: 0.32
A12: 11 | B12: 40544 | C12: 1 | D12: 0 | E12: 1 | F12: 10 | H12: FALSE | I12: 6 | J12: 1 | M12: 0.38
A13: 12 | B13: 40544 | C13: 1 | D13: 0 | E13: 1 | F13: 11 | H13: FALSE | I13: 6 | J13: 1 | M13: 0.36
... A611: 610 | B611: 40571 | C611: 1 | D611: 0 | E611: 1 | F611: 15 | H611: FALSE | I611: 5 | J611: 2 | M611: 0.2

Sheet Findings on DB1
A2: Daywise weather situation | H2: Daily Average temperature | K2: Analysis | L2: Value
A3: Count of Weather_Situation | B3: Weather | H3: Row Labels | I3: Average of Temperature | K3: Total number of instances | L3: =+COUNT(Dataset_1!A2:A611) -> 610
A4: Days | B4: 1 | C4: 2 | D4: 3 | E4: 4 | F4: Grand Total | H4: 0 | I4: 0.20702128 | K4: Days Count | L4: =COUNT(Dataset_1!I2:I611) -> 610
A5: 0 | B5: 70 | C5: 19 | D5: 5 | F5: 94 | H5: 1 | I5: 0.15483871 | K5: Average Temp | L5: =AVERAGE(Dataset_1!M2:M611) -> 0.19688525
A6: 1 | B6: 57 | C6: 31 | D6: 5 | F6: 93 | H6: 2 | I6: 0.20075 | K6: Max_Temp | L6: =MAX(Dataset_1!M2:M611) -> 0.46
A7: 2 | B7: 33 | C7: 41 | D7: 6 | F7: 80 | H7: 3 | I7: 0.22880952 | K7: Min_Temp | L7: =MIN(Dataset_1!M2:M611) -> 0.02
A8: 3 | B8: 54 | C8: 13 | D8: 16 | E8: 1 | F8: 84 | H8: 4 | I8: 0.20886076 | K8: Most visited day | L8: =MAX(Dataset_1!I2:I611) -> 6
A9: 4 | B9: 56 | C9: 23 | F9: 79 | H9: 5 | I9: 0.17976471 | K9: Least visited day | L9: =MIN(Dataset_1!I2:I611) -> 0
A10: 5 | B10: 48 | C10: 28 | D10: 9 | F10: 85 | H10: 6 | I10: 0.20189474 | K10: Average Visited day | L10: =AVERAGE(Dataset_1!I2:I611) -> 2.9770492
A11: 6 | B11: 50 | C11: 39 | D11: 6 | F11: 95 | H11: Grand Total | I11: 0.19688525
A12: Grand Total | B12: 368 | C12: 194 | D12: 47 | E12: 1 | F12: 610
H21: Weather situation based on the days
H23: Weather_Situations | I23: Column Labels
H24: Days | I24: 1 | J24: 2 | K24: 3 | L24: 4 | M24: Grand Total
H25: 0 | I25: 70 | J25: 19 | K25: 5 | M25: 94
H26: 1 | I26: 57 | J26: 31 | K26: 5 | M26: 93
H27: 2 | I27: 33 | J27: 41 | K27: 6 | M27: 80
H28: 3 | I28: 54 | J28: 13 | K28: 16 | L28: 1 | M28: 84
H29: 4 | I29: 56 | J29: 23 | M29: 79
H30: 5 | I30: 48 | J30: 28 | K30: 9 | M30: 85
H31: 6 | I31: 50 | J31: 39 | K31: 6 | M31: 95
H32: Grand Total | I32: 368 | J32: 194 | K32: 47 | L32: 1 | M32: 610
A44: Row Labels | B44: Average of Weather_Situation | C44: Count of holiday
A45: FALSE | B45: 1.4488055 | C45: 586
A46: TRUE | B46: 2.1666667 | C46: 24
A47: Grand Total | B47: 1.4770492 | C47: 610

Sheet Dataset_2
A1: Unnamed: 0 | B1: Instant | C1: Atemp | D1: Humidity | E1: Windspeed | F1: Casual Customer | G1: Registered Customer | H1: Total Customers
A2: 0 | B2: 1 | C2: 0.2879 | D2: 0.81 | E2: 0 | F2: 3 | G2: 13 | H2: 16
A3: 1 | B3: 2 | C3: 0.2727 | D3: 0.8 | E3: 0 | F3: 8 | G3: 32 | H3: 40
A4: 2 | B4: 3 | C4: 0.2727 | D4: 0.8 | E4: 0 | F4: 5 | G4: 27 | H4: 32
A5: 3 | B5: 4 | C5: 0.2879 | D5: 0.75 | E5: 0 | F5: 3 | G5: 10 | H5: 13
A6: 4 | B6: 5 | C6: 0.2879 | D6: 0.75 | E6: 0 | F6: 0 | G6: 1 | H6: 1
A7: 5 | B7: 6 | C7: 0.2576 | D7: 0.75 | E7: 0.0896 | F7: 0 | G7: 1 | H7: 1
A8: 6 | B8: 7 | C8: 0.2727 | D8: 0.8 | E8: 0 | F8: 2 | G8: 0 | H8: 2
A9: 7 | B9: 8 | C9: 0.2576 | D9: 0.86 | E9: 0 | F9: 1 | G9: 2 | H9: 3
A10: 8 | B10: 9 | C10: 0.1999 | D10: 0.75 | E10: 0 | F10: 1 | G10: 7 | H10: 8
A11: 9 | B11: 10 | C11: 0.3485 | D11: 0.76 | E11: 0 | F11: 8 | G11: 6 | H11: 14
A12: 10 | B12: 11 | C12: 0.3939 | D12: 0.76 | E12: 0.2537 | F12: 12 | G12: 24 | H12: 36
A13: 11 | B13: 12 | C13: 0.3333 | D13: 0.81 | E13: 0.2836 | F13: 26 | G13: 30 | H13: 56
... A611: 609 | B611: 610 | C611: 0.2576 | D611: 0.86 | E611: 0 | F611: 1 | G611: 40 | H611: 41

Sheet Findings on DB2
F2: This data shows the Customers based on the Windspeed
B3: Data anylysis | C3: Values | F3: Windspeed | G3: Casual Customers | H3: Registered Customers | I3: Total Customers
B4: Min atemp | C4: =MIN(Dataset_2!C2:C611) -> 0 | F4: 0 | G4: 253 | H4: 3151 | I4: 3404
B5: Max atemp | C5: =MAX(Dataset_2!C2:C611) -> 0.4545 | F5: 0.0896 | G5: 116 | H5: 2362 | I5: 2478
B6: Average atemp | C6: =AVERAGE(Dataset_2!C2:C611) -> 0.19993426 | F6: 0.1045 | G6: 122 | H6: 2530 | I6: 2652
B7: Min humidity | C7: =MIN(Dataset_2!D2:D611) -> 0.21 | F7: 0.1343 | G7: 164 | H7: 2329 | I7: 2493
B8: Max humidity | C8: =MAX(Dataset_2!D2:D611) -> 1 | F8: 0.1642 | G8: 251 | H8: 3118 | I8: 3369
B9: Average humidity | C9: =AVERAGE(Dataset_2!D2:D611) -> 0.56247541 | F9: 0.194 | G9: 238 | H9: 2789 | I9: 3027
B10: Min windspeed | C10: =MIN(Dataset_2!E2:E611) -> 0 | F10: 0.2239 | G10: 206 | H10: 2338 | I10: 2544
B11: Max windspeed | C11: =MAX(Dataset_2!E2:E611) -> 0.5821 | F11: 0.2537 | G11: 358 | H11: 2425 | I11: 2783
B12: Average windspeed | C12: =AVERAGE(Dataset_2!E2:E611) -> 0.20485098 | F12: 0.2836 | G12: 305 | H12: 2519 | I12: 2824
B13: Max Rides | C13: =MAX(Dataset_2!H2:H611) -> 249 | F13: 0.2985 | G13: 272 | H13: 1426 | I13: 1698
B14: Minimum Rides | C14: =MIN(Dataset_2!H2:H611) -> 1 | F14: 0.3284 | G14: 160 | H14: 2177 | I14: 2337
F15: 0.3582 | G15: 74 | H15: 1177 | I15: 1251
F16: 0.3881 | G16: 67 | H16: 801 | I16: 868
F17: 0.4179 | G17: 17 | H17: 442 | I17: 459
F18: 0.4478 | G18: 48 | H18: 622 | I18: 670
F19: 0.4627 | G19: 46 | H19: 358 | I19: 404
F20: 0.4925 | G20: 12 | H20: 83 | I20: 95
F21: 0.5224 | G21: 10 | H21: 257 | I21: 267
F22: 0.5522 | G22: 5 | H22: 64 | I22: 69
F23: 0.5821 | G23: 22 | H23: 184 | I23: 206
F24: Grand Total | G24: 2746 | H24: 31152 | I24: 33898
A50: Row Labels | B50: Sum of Casual Customer | C50: Sum of registered Customer | D50: Sum of cnt
A51: 0.21 | B51: 8 | C51: 65 | D51: 73
A52: 0.25 | B52: 6 | C52: 56 | D52: 62
A53: 0.26 | B53: 18 | C53: 264 | D53: 282
A54: 0.27 | B54: 11 | C54: 67 | D54: 78
A55: 0.28 | B55: 90 | C55: 724 | D55: 814
A56: 0.29 | B56: 8 | C56: 68 | D56: 76
A57: 0.3 | B57: 65 | C57: 703 | D57: 768
A58: 0.32 | B58: 34 | C58: 364 | D58: 398
A59: 0.33 | B59: 41 | C59: 299 | D59: 340
A60: 0.34 | B60: 52 | C60: 243 | D60: 295
A61: 0.35 | B61: 85 | C61: 585 | D61: 670
A62: 0.36 | B62: 105 | C62: 482 | D62: 587
... A111: 1 | B111: 1 | C111: 8 | D111: 9
A112: Grand Total | B112: 2746 | C112: 31152 | D112: 33898

Sheet Merged Database 1&2
A1: Instant | B1: Date | C1: Season | D1: Year | E1: Month | F1: Hour | G1: Time Category | H1: Holiday | I1: Weekday | J1: Weather_Situation | K1: Temperature | L1: Atemp | M1: Humidity | N1: Windspeed | O1: Casual Customer | P1: Registered Customer | Q1: Total
A2: 1 | B2: 40544 | C2: 1 | D2: 0 | E2: 1 | F2: 0 | G2: {=_xlfn.IFS(F2<3,"Night",F2<=6,"Early Morning",F2<8,"Morning",F2<10,"Late Morning",F2<12,"Afternoon",F2<16,"Afternoon",F2<=18,"Early Evening",F2<=20,"Evening",F2<=22,"Late Evening",F2<=23,"Night")} -> Night | H2: FALSE | I2: 6 | J2: 1 | K2: 0.24 | L2: 0.2879 | M2: 0.81 | N2: 0 | O2: 3 | P2: 13 | Q2: 16
A3: 2 | B3: 40544 | C3: 1 | D3: 0 | E3: 1 | F3: 1 | G3: {=_xlfn.IFS(F3<3,"Night",F3<=6,"Early Morning",F3<8,"Morning",F3<10,"Late Morning",F3<12,"Afternoon",F3<16,"Afternoon",F3<=18,"Early Evening",F3<=20,"Evening",F3<=22,"Late Evening",F3<=23,"Night")} -> Night | H3: FALSE | I3: 6 | J3: 1 | K3: 0.22 | L3: 0.2727 | M3: 0.8 | N3: 0 | O3: 8 | P3: 32 | Q3: 40
A4: 3 | B4: 40544 | C4: 1 | D4: 0 | E4: 1 | F4: 2 | G4: {=_xlfn.IFS(F4<3,"Night",F4<=6,"Early Morning",F4<8,"Morning",F4<10,"Late Morning",F4<12,"Afternoon",F4<16,"Afternoon",F4<=18,"Early Evening",F4<=20,"Evening",F4<=22,"Late Evening",F4<=23,"Night")} -> Night | H4: FALSE | I4: 6 | J4: 1 | K4: 0.22 | L4: 0.2727 | M4: 0.8 | N4: 0 | O4: 5 | P4: 27 | Q4: 32
A5: 4 | B5: 40544 | C5: 1 | D5: 0 | E5: 1 | F5: 3 | G5: {=_xlfn.IFS(F5<3,"Night",F5<=6,"Early Morning",F5<8,"Morning",F5<10,"Late Morning",F5<12,"Afternoon",F5<16,"Afternoon",F5<=18,"Early Evening",F5<=20,"Evening",F5<=22,"Late Evening",F5<=23,"Night")} -> Early Morning | H5: FALSE | I5: 6 | J5: 1 | K5: 0.24 | L5: 0.2879 | M5: 0.75 | N5: 0 | O5: 3 | P5: 10 | Q5: 13
A6: 5 | B6: 40544 | C6: 1 | D6: 0 | E6: 1 | F6: 4 | G6: {=_xlfn.IFS(F6<3,"Night",F6<=6,"Early Morning",F6<8,"Morning",F6<10,"Late Morning",F6<12,"Afternoon",F6<16,"Afternoon",F6<=18,"Early Evening",F6<=20,"Evening",F6<=22,"Late Evening",F6<=23,"Night")} -> Early Morning | H6: FALSE | I6: 6 | J6: 1 | K6: 0.24 | L6: 0.2879 | M6: 0.75 | N6: 0 | O6: 0 | P6: 1 | Q6: 1
A7: 6 | B7: 40544 | C7: 1 | D7: 0 | E7: 1 | F7: 5 | G7: {=_xlfn.IFS(F7<3,"Night",F7<=6,"Early Morning",F7<8,"Morning",F7<10,"Late Morning",F7<12,"Afternoon",F7<16,"Afternoon",F7<=18,"Early Evening",F7<=20,"Evening",F7<=22,"Late Evening",F7<=23,"Night")} -> Early Morning | H7: FALSE | I7: 6 | J7: 2 | K7: 0.24 | L7: 0.2576 | M7: 0.75 | N7: 0.0896 | O7: 0 | P7: 1 | Q7: 1
A8: 7 | B8: 40544 | C8: 1 | D8: 0 | E8: 1 | F8: 6 | G8: {=_xlfn.IFS(F8<3,"Night",F8<=6,"Early Morning",F8<8,"Morning",F8<10,"Late Morning",F8<12,"Afternoon",F8<16,"Afternoon",F8<=18,"Early Evening",F8<=20,"Evening",F8<=22,"Late Evening",F8<=23,"Night")} -> Early Morning | H8: FALSE | I8: 6 | J8: 1 | K8: 0.22 | L8: 0.2727 | M8: 0.8 | N8: 0 | O8: 2 | P8: 0 | Q8: 2
A9: 8 | B9: 40544 | C9: 1 | D9: 0 | E9: 1 | F9: 7 | G9: {=_xlfn.IFS(F9<3,"Night",F9<=6,"Early Morning",F9<8,"Morning",F9<10,"Late Morning",F9<12,"Afternoon",F9<16,"Afternoon",F9<=18,"Early Evening",F9<=20,"Evening",F9<=22,"Late Evening",F9<=23,"Night")} -> Morning | H9: FALSE | I9: 6 | J9: 1 | K9: 0.2 | L9: 0.2576 | M9: 0.86 | N9: 0 | O9: 1 | P9: 2 | Q9: 3
A10: 9 | B10: 40544 | C10: 1 | D10: 0 | E10: 1 | F10: 8 | G10: {=_xlfn.IFS(F10<3,"Night",F10<=6,"Early Morning",F10<8,"Morning",F10<10,"Late Morning",F10<12,"Afternoon",F10<16,"Afternoon",F10<=18,"Early Evening",F10<=20,"Evening",F10<=22,"Late Evening",F10<=23,"Night")} -> Late Morning | H10: FALSE | I10: 6 | J10: 1 | K10: 0.24 | L10: 0.1999 | M10: 0.75 | N10: 0 | O10: 1 | P10: 7 | Q10: 8
A11: 10 | B11: 40544 | C11: 1 | D11: 0 | E11: 1 | F11: 9 | G11: {=_xlfn.IFS(F11<3,"Night",F11<=6,"Early Morning",F11<8,"Morning",F11<10,"Late Morning",F11<12,"Afternoon",F11<16,"Afternoon",F11<=18,"Early Evening",F11<=20,"Evening",F11<=22,"Late Evening",F11<=23,"Night")} -> Late Morning | H11: FALSE | I11: 6 | J11: 1 | K11: 0.32 | L11: 0.3485 | M11: 0.76 | N11: 0 | O11: 8 | P11: 6 | Q11: 14
A12: 11 | B12: 40544 | C12: 1 | D12: 0 | E12: 1 | F12: 10 | G12: {=_xlfn.IFS(F12<3,"Night",F12<=6,"Early Morning",F12<8,"Morning",F12<10,"Late Morning",F12<12,"Afternoon",F12<16,"Afternoon",F12<=18,"Early Evening",F12<=20,"Evening",F12<=22,"Late Evening",F12<=23,"Night")} -> Afternoon | H12: FALSE | I12: 6 | J12: 1 | K12: 0.38 | L12: 0.3939 | M12: 0.76 | N12: 0.2537 | O12: 12 | P12: 24 | Q12: 36
A13: 12 | B13: 40544 | C13: 1 | D13: 0 | E13: 1 | F13: 11 | G13: {=_xlfn.IFS(F13<3,"Night",F13<=6,"Early Morning",F13<8,"Morning",F13<10,"Late Morning",F13<12,"Afternoon",F13<16,"Afternoon",F13<=18,"Early Evening",F13<=20,"Evening",F13<=22,"Late Evening",F13<=23,"Night")} -> Afternoon | H13: FALSE | I13: 6 | J13: 1 | K13: 0.36 | L13: 0.3333 | M13: 0.81 | N13: 0.2836 | O13: 26 | P13: 30 | Q13: 56
... A611: 610 | B611: 40571 | C611: 1 | D611: 0 | E611: 1 | F611: 15 | G611: {=_xlfn.IFS(F611<3,"Night",F611<=6,"Early Morning",F611<8,"Morning",F611<10,"Late Morning",F611<12,"Afternoon",F611<16,"Afternoon",F611<=18,"Early Evening",F611<=20,"Evening",F611<=22,"Late Evening",F611<=23,"Night")} -> Afternoon | H611: FALSE | I611: 5 | J611: 2 | K611: 0.2 | L611: 0.2576 | M611: 0.86 | N611: 0 | O611: 1 | P611: 40 | Q611: 41

Sheet Analysis on DB1&2
A6: Daily Bikerides by Customers Type
A8: Days | B8: Casual Customers | C8: Registered Customers
A9: 0 | B9: 94 | C9: 94
A10: 1 | B10: 93 | C10: 93
A11: 2 | B11: 80 | C11: 80
A12: 3 | B12: 84 | C12: 84
A13: 4 | B13: 79 | C13: 79
A14: 5 | B14: 85 | C14: 85
A15: 6 | B15: 95 | C15: 95
A16: Grand Total | B16: 610 | C16: 610

Sheet Sheet4
A1: 🚲 Total Riders | C1: ⚡ Avg/Hr | E1: 🏆 Peak Hours | G1: Median Riders/Hr 📊 | I1: ✅ Registered Riders | K1: 👥 Casual Riders
A2: =+SUM('Combined Dataset'!T2:T1001) -> 58304 | C2: =ROUNDUP(AVERAGE('Combined Dataset'!T2:T1001),0) -> 59 | E2: =MAX('Combined Dataset'!T:T) -> 249 | G2: =MEDIAN('Combined Dataset'!T1:T1001) -> 49 | I2: =SUM('Combined Dataset'!S2:S1001) -> 53383 | K2: =SUM('Combined Dataset'!R2:R1001) -> 4921
A4: Weather Conditions
A5: Condition | B5: Riders | C5: Share | D5: Avg/Hr | E5: Peak
A6: 1 | B6: =ROUNDUP(SUMIF(Table4[Weather_Situation],"=1",(Table4[cnt])),0) -> 37373 | C6: =ROUNDUP(B6/SUM($B$6:$B$9)*100,0)&"%" -> 65% | D6: =ROUNDUP(AVERAGEIF(Table4[Weather_Situation],"=1",(Table4[cnt])),0) -> 62 | E6: =ROUNDUP(_xlfn.MAXIFS(Table4[cnt],Table4[Weather_Situation],"=1"),0) -> 249
A7: 2 | B7: =ROUNDUP(SUMIF(Table4[Weather_Situation],"=2",(Table4[cnt])),0) -> 18106 | C7: =ROUNDUP(B7/SUM($B$6:$B$9)*100,0)&"%" -> 32% | D7: =ROUNDUP(AVERAGEIF(Table4[Weather_Situation],"=2",(Table4[cnt])),0) -> 59 | E7: =ROUNDUP(_xlfn.MAXIFS(Table4[cnt],Table4[Weather_Situation],"=2"),0) -> 238
A8: 3 | B8: =ROUNDUP(SUMIF(Table4[Weather_Situation],"=3",(Table4[cnt])),0) -> 2789 | C8: =ROUNDUP(B8/SUM($B$6:$B$9)*100,0)&"%" -> 5% | D8: =ROUNDUP(AVERAGEIF(Table4[Weather_Situation],"=3",(Table4[cnt])),0) -> 34 | E8: =ROUNDUP(_xlfn.MAXIFS(Table4[cnt],Table4[Weather_Situation],"=3"),0) -> 155
A9: 4 | B9: =ROUNDUP(SUMIF(Table4[Weather_Situation],"=4",(Table4[cnt])),0) -> 36 | C9: =ROUNDUP(B9/SUM($B$6:$B$9)*100,0)&"%" -> 1% | D9: =ROUNDUP(AVERAGEIF(Table4[Weather_Situation],"=4",(Table4[cnt])),0) -> 36 | E9: =ROUNDUP(_xlfn.MAXIFS(Table4[cnt],Table4[Weather_Situation],"=4"),0) -> 36

Sheet Combined Dataset
A1: Instant | B1: Date | C1: Season | D1: Year | E1: Month | F1: Hour | G1: Time of day | H1: Holiday | I1: Weekday | J1: Weather_Situation | K1: Temperature | L1: Temp Category | M1: Atemp | N1: Humidity | O1: Humid Cat | P1: Windspeed | Q1: Windspeed category | R1: Casual Customer | S1: registered Customer | T1: cnt | U1: Rides Demand
A2: 1 | B2: 40544 | C2: 1 | D2: 0 | E2: 1 | F2: 0 | G2: {=_xlfn.IFS(F2<4,"Night",F2<=6,"Early Morning",F2<11,"Morning",F2<12,"Afternoon",F2<=16,"Afternoon",F2<=20,"Evening",F2>=21,"Night")} -> Night | H2: FALSE | I2: 6 | J2: 1 | K2: 0.24 | L2: {=_xlfn.IFS(K2<0.15,"Cold",K2<0.25,"Mild",K2<=0.32,"Warm",K2>=0.33,"Hot")} -> Mild | M2: 0.2879 | N2: 0.81 | O2: {=_xlfn.IFS(N2>0.61, "High Humidity", N2>=0.6, "Humid", N2>0.4, "Less Humidity", TRUE, "Dry")} -> High Humidity | P2: 0 | Q2: {=_xlfn.IFS(P2<=0.2,"Low Windspeed",P2<0.4,"Medium Windspeed",P2>=0.41,"High Windspeed")} -> Low Windspeed | R2: 3 | S2: 13 | T2: 16 | U2: {=_xlfn.IFS(T2<=70,"Low",T2<=160,"Medium",T2>=161,"High")} -> Low
A3: 2 | B3: 40544 | C3: 1 | D3: 0 | E3: 1 | F3: 1 | G3: {=_xlfn.IFS(F3<4,"Night",F3<=6,"Early Morning",F3<11,"Morning",F3<12,"Afternoon",F3<=16,"Afternoon",F3<=20,"Evening",F3>=21,"Night")} -> Night | H3: FALSE | I3: 6 | J3: 1 | K3: 0.22 | L3: {=_xlfn.IFS(K3<0.15,"Cold",K3<0.25,"Mild",K3<=0.32,"Warm",K3>=0.33,"Hot")} -> Mild | M3: 0.2727 | N3: 0.8 | O3: {=_xlfn.IFS(N3>0.61, "High Humidity", N3>=0.6, "Humid", N3>0.4, "Less Humidity", TRUE, "Dry")} -> High Humidity | P3: 0 | Q3: {=_xlfn.IFS(P3<=0.2,"Low Windspeed",P3<0.4,"Medium Windspeed",P3>=0.41,"High Windspeed")} -> Low Windspeed | R3: 8 | S3: 32 | T3: 40 | U3: {=_xlfn.IFS(T3<=70,"Low",T3<=160,"Medium",T3>=161,"High")} -> Low
A4: 3 | B4: 40544 | C4: 1 | D4: 0 | E4: 1 | F4: 2 | G4: {=_xlfn.IFS(F4<4,"Night",F4<=6,"Early Morning",F4<11,"Morning",F4<12,"Afternoon",F4<=16,"Afternoon",F4<=20,"Evening",F4>=21,"Night")} -> Night | H4: FALSE | I4: 6 | J4: 1 | K4: 0.22 | L4: {=_xlfn.IFS(K4<0.15,"Cold",K4<0.25,"Mild",K4<=0.32,"Warm",K4>=0.33,"Hot")} -> Mild | M4: 0.2727 | N4: 0.8 | O4: {=_xlfn.IFS(N4>0.61, "High Humidity", N4>=0.6, "Humid", N4>0.4, "Less Humidity", TRUE, "Dry")} -> High Humidity | P4: 0 | Q4: {=_xlfn.IFS(P4<=0.2,"Low Windspeed",P4<0.4,"Medium Windspeed",P4>=0.41,"High Windspeed")} -> Low Windspeed | R4: 5 | S4: 27 | T4: 32 | U4: {=_xlfn.IFS(T4<=70,"Low",T4<=160,"Medium",T4>=161,"High")} -> Low
A5: 4 | B5: 40544 | C5: 1 | D5: 0 | E5: 1 | F5: 3 | G5: {=_xlfn.IFS(F5<4,"Night",F5<=6,"Early Morning",F5<11,"Morning",F5<12,"Afternoon",F5<=16,"Afternoon",F5<=20,"Evening",F5>=21,"Night")} -> Night | H5: FALSE | I5: 6 | J5: 1 | K5: 0.24 | L5: {=_xlfn.IFS(K5<0.15,"Cold",K5<0.25,"Mild",K5<=0.32,"Warm",K5>=0.33,"Hot")} -> Mild | M5: 0.2879 | N5: 0.75 | O5: {=_xlfn.IFS(N5>0.61, "High Humidity", N5>=0.6, "Humid", N5>0.4, "Less Humidity", TRUE, "Dry")} -> High Humidity | P5: 0 | Q5: {=_xlfn.IFS(P5<=0.2,"Low Windspeed",P5<0.4,"Medium Windspeed",P5>=0.41,"High Windspeed")} -> Low Windspeed | R5: 3 | S5: 10 | T5: 13 | U5: {=_xlfn.IFS(T5<=70,"Low",T5<=160,"Medium",T5>=161,"High")} -> Low
A6: 5 | B6: 40544 | C6: 1 | D6: 0 | E6: 1 | F6: 4 | G6: {=_xlfn.IFS(F6<4,"Night",F6<=6,"Early Morning",F6<11,"Morning",F6<12,"Afternoon",F6<=16,"Afternoon",F6<=20,"Evening",F6>=21,"Night")} -> Early Morning | H6: FALSE | I6: 6 | J6: 1 | K6: 0.24 | L6: {=_xlfn.IFS(K6<0.15,"Cold",K6<0.25,"Mild",K6<=0.32,"Warm",K6>=0.33,"Hot")} -> Mild | M6: 0.2879 | N6: 0.75 | O6: {=_xlfn.IFS(N6>0.61, "High Humidity", N6>=0.6, "Humid", N6>0.4, "Less Humidity", TRUE, "Dry")} -> High Humidity | P6: 0 | Q6: {=_xlfn.IFS(P6<=0.2,"Low Windspeed",P6<0.4,"Medium Windspeed",P6>=0.41,"High Windspeed")} -> Low Windspeed | R6: 0 | S6: 1 | T6: 1 | U6: {=_xlfn.IFS(T6<=70,"Low",T6<=160,"Medium",T6>=161,"High")} -> Low
A7: 6 | B7: 40544 | C7: 1 | D7: 0 | E7: 1 | F7: 5 | G7: {=_xlfn.IFS(F7<4,"Night",F7<=6,"Early Morning",F7<11,"Morning",F7<12,"Afternoon",F7<=16,"Afternoon",F7<=20,"Evening",F7>=21,"Night")} -> Early Morning | H7: FALSE | I7: 6 | J7: 2 | K7: 0.24 | L7: {=_xlfn.IFS(K7<0.15,"Cold",K7<0.25,"Mild",K7<=0.32,"Warm",K7>=0.33,"Hot")} -> Mild | M7: 0.2576 | N7: 0.75 | O7: {=_xlfn.IFS(N7>0.61, "High Humidity", N7>=0.6, "Humid", N7>0.4, "Less Humidity", TRUE, "Dry")} -> High Humidity | P7: 0.0896 | Q7: {=_xlfn.IFS(P7<=0.2,"Low Windspeed",P7<0.4,"Medium Windspeed",P7>=0.41,"High Windspeed")} -> Low Windspeed | R7: 0 | S7: 1 | T7: 1 | U7: {=_xlfn.IFS(T7<=70,"Low",T7<=160,"Medium",T7>=161,"High")} -> Low
A8: 7 | B8: 40544 | C8: 1 | D8: 0 | E8: 1 | F8: 6 | G8: {=_xlfn.IFS(F8<4,"Night",F8<=6,"Early Morning",F8<11,"Morning",F8<12,"Afternoon",F8<=16,"Afternoon",F8<=20,"Evening",F8>=21,"Night")} -> Early Morning | H8: FALSE | I8: 6 | J8: 1 | K8: 0.22 | L8: {=_xlfn.IFS(K8<0.15,"Cold",K8<0.25,"Mild",K8<=0.32,"Warm",K8>=0.33,"Hot")} -> Mild | M8: 0.2727 | N8: 0.8 | O8: {=_xlfn.IFS(N8>0.61, "High Humidity", N8>=0.6, "Humid", N8>0.4, "Less Humidity", TRUE, "Dry")} -> High Humidity | P8: 0 | Q8: {=_xlfn.IFS(P8<=0.2,"Low Windspeed",P8<0.4,"Medium Windspeed",P8>=0.41,"High Windspeed")} -> Low Windspeed | R8: 2 | S8: 0 | T8: 2 | U8: {=_xlfn.IFS(T8<=70,"Low",T8<=160,"Medium",T8>=161,"High")} -> Low
A9: 8 | B9: 40544 | C9: 1 | D9: 0 | E9: 1 | F9: 7 | G9: {=_xlfn.IFS(F9<4,"Night",F9<=6,"Early Morning",F9<11,"Morning",F9<12,"Afternoon",F9<=16,"Afternoon",F9<=20,"Evening",F9>=21,"Night")} -> Morning | H9: FALSE | I9: 6 | J9: 1 | K9: 0.2 | L9: {=_xlfn.IFS(K9<0.15,"Cold",K9<0.25,"Mild",K9<=0.32,"Warm",K9>=0.33,"Hot")} -> Mild | M9: 0.2576 | N9: 0.86 | O9: {=_xlfn.IFS(N9>0.61, "High Humidity", N9>=0.6, "Humid", N9>0.4, "Less Humidity", TRUE, "Dry")} -> High Humidity | P9: 0 | Q9: {=_xlfn.IFS(P9<=0.2,"Low Windspeed",P9<0.4,"Medium Windspeed",P9>=0.41,"High Windspeed")} -> Low Windspeed | R9: 1 | S9: 2 | T9: 3 | U9: {=_xlfn.IFS(T9<=70,"Low",T9<=160,"Medium",T9>=161,"High")} -> Low
A10: 9 | B10: 40544 | C10: 1 | D10: 0 | E10: 1 | F10: 8 | G10: {=_xlfn.IFS(F10<4,"Night",F10<=6,"Early Morning",F10<11,"Morning",F10<12,"Afternoon",F10<=16,"Afternoon",F10<=20,"Evening",F10>=21,"Night")} -> Morning | H10: FALSE | I10: 6 | J10: 1 | K10: 0.24 | L10: {=_xlfn.IFS(K10<0.15,"Cold",K10<0.25,"Mild",K10<=0.32,"Warm",K10>=0.33,"Hot")} -> Mild | M10: 0.1999 | N10: 0.75 | O10: {=_xlfn.IFS(N10>0.61, "High Humidity", N10>=0.6, "Humid", N10>0.4, "Less Humidity", TRUE, "Dry")} -> High Humidity | P10: 0 | Q10: {=_xlfn.IFS(P10<=0.2,"Low Windspeed",P10<0.4,"Medium Windspeed",P10>=0.41,"High Windspeed")} -> Low Windspeed | R10: 1 | S10: 7 | T10: 8 | U10: {=_xlfn.IFS(T10<=70,"Low",T10<=160,"Medium",T10>=161,"High")} -> Low
A11: 10 | B11: 40544 | C11: 1 | D11: 0 | E11: 1 | F11: 9 | G11: {=_xlfn.IFS(F11<4,"Night",F11<=6,"Early Morning",F11<11,"Morning",F11<12,"Afternoon",F11<=16,"Afternoon",F11<=20,"Evening",F11>=21,"Night")} -> Morning | H11: FALSE | I11: 6 | J11: 1 | K11: 0.32 | L11: {=_xlfn.IFS(K11<0.15,"Cold",K11<0.25,"Mild",K11<=0.32,"Warm",K11>=0.33,"Hot")} -> Warm | M11: 0.3485 | N11: 0.76 | O11: {=_xlfn.IFS(N11>0.61, "High Humidity", N11>=0.6, "Humid", N11>0.4, "Less Humidity", TRUE, "Dry")} -> High Humidity | P11: 0 | Q11: {=_xlfn.IFS(P11<=0.2,"Low Windspeed",P11<0.4,"Medium Windspeed",P11>=0.41,"High Windspeed")} -> Low Windspeed | R11: 8 | S11: 6 | T11: 14 | U11: {=_xlfn.IFS(T11<=70,"Low",T11<=160,"Medium",T11>=161,"High")} -> Low
A12: 11 | B12: 40544 | C12: 1 | D12: 0 | E12: 1 | F12: 10 | G12: {=_xlfn.IFS(F12<4,"Night",F12<=6,"Early Morning",F12<11,"Morning",F12<12,"Afternoon",F12<=16,"Afternoon",F12<=20,"Evening",F12>=21,"Night")} -> Morning | H12: FALSE | I12: 6 | J12: 1 | K12: 0.38 | L12: {=_xlfn.IFS(K12<0.15,"Cold",K12<0.25,"Mild",K12<=0.32,"Warm",K12>=0.33,"Hot")} -> Hot | M12: 0.3939 | N12: 0.76 | O12: {=_xlfn.IFS(N12>0.61, "High Humidity", N12>=0.6, "Humid", N12>0.4, "Less Humidity", TRUE, "Dry")} -> High Humidity | P12: 0.2537 | Q12: {=_xlfn.IFS(P12<=0.2,"Low Windspeed",P12<0.4,"Medium Windspeed",P12>=0.41,"High Windspeed")} -> Medium Windspeed | R12: 12 | S12: 24 | T12: 36 | U12: {=_xlfn.IFS(T12<=70,"Low",T12<=160,"Medium",T12>=161,"High")} -> Low
A13: 12 | B13: 40544 | C13: 1 | D13: 0 | E13: 1 | F13: 11 | G13: {=_xlfn.IFS(F13<4,"Night",F13<=6,"Early Morning",F13<11,"Morning",F13<12,"Afternoon",F13<=16,"Afternoon",F13<=20,"Evening",F13>=21,"Night")} -> Afternoon | H13: FALSE | I13: 6 | J13: 1 | K13: 0.36 | L13: {=_xlfn.IFS(K13<0.15,"Cold",K13<0.25,"Mild",K13<=0.32,"Warm",K13>=0.33,"Hot")} -> Hot | M13: 0.3333 | N13: 0.81 | O13: {=_xlfn.IFS(N13>0.61, "High Humidity", N13>=0.6, "Humid", N13>0.4, "Less Humidity", TRUE, "Dry")} -> High Humidity | P13: 0.2836 | Q13: {=_xlfn.IFS(P13<=0.2,"Low Windspeed",P13<0.4,"Medium Windspeed",P13>=0.41,"High Windspeed")} -> Medium Windspeed | R13: 26 | S13: 30 | T13: 56 | U13: {=_xlfn.IFS(T13<=70,"Low",T13<=160,"Medium",T13>=161,"High")} -> Low
... A1001: 1000 | B1001: 40588 | C1001: 1 | D1001: 0 | E1001: 2 | F1001: 7 | G1001: {=_xlfn.IFS(F1001<4,"Night",F1001<=6,"Early Morning",F1001<11,"Morning",F1001<12,"Afternoon",F1001<=16,"Afternoon",F1001<=20,"Evening",F1001>=21,"Night")} -> Morning | H1001: FALSE | I1001: 1 | J1001: 1 | K1001: 0.34 | L1001: {=_xlfn.IFS(K1001<0.15,"Cold",K1001<0.25,"Mild",K1001<=0.32,"Warm",K1001>=0.33,"Hot")} -> Hot | M1001: 0.303 | N1001: 0.46 | O1001: {=_xlfn.IFS(N1001>0.61, "High Humidity", N1001>=0.6, "Humid", N1001>0.4, "Less Humidity", TRUE, "Dry")} -> Less Humidity | P1001: 0.2985 | Q1001: {=_xlfn.IFS(P1001<=0.2,"Low Windspeed",P1001<0.4,"Medium Windspeed",P1001>=0.41,"High Windspeed")} -> Medium Windspeed | R1001: 2 | S1001: 96 | T1001: 98 | U1001: {=_xlfn.IFS(T1001<=70,"Low",T1001<=160,"Medium",T1001>=161,"High")} -> Medium

Sheet Dashboard Final
A1: 🚲 Total Riders | C1: ⚡ Avg/Hr | E1: 🏆 Peak Hours | G1: Median Riders/Hr 📊 | I1: ✅ Registered Riders | K1: 👥 Casual Riders
A2: =+SUM('Combined Dataset'!T2:T1001) -> 58304 | C2: =ROUNDUP(AVERAGE('Combined Dataset'!T2:T1001),0) -> 59 | E2: =MAX('Combined Dataset'!T:T) -> 249 | G2: =MEDIAN('Combined Dataset'!T1:T1001) -> 49 | I2: =SUM('Combined Dataset'!S2:S1001) -> 53383 | K2: =SUM('Combined Dataset'!R2:R1001) -> 4921

Sheet Descriptive Data
A1: 🚲 Total Riders | C1: ⚡ Avg/Hr | E1: 🏆 Peak Hours | G1: Median Riders/Hr 📊 | I1: ✅ Registered Riders | K1: 👥 Casual Riders
A2: =+SUM('Combined Dataset'!T2:T1001) -> 58304 | C2: =ROUNDUP(AVERAGE('Combined Dataset'!T2:T1001),0) -> 59 | E2: =MAX('Combined Dataset'!T:T) -> 249 | G2: =MEDIAN('Combined Dataset'!T1:T1001) -> 49 | I2: =SUM('Combined Dataset'!S2:S1001) -> 53383 | K2: =SUM('Combined Dataset'!R2:R1001) -> 4921
B16: Day | C16: Casual Customers | D16: Registered Customers
B17: 0 | C17: 1477 | D17: 6644
B18: 1 | C18: 534 | D18: 7916
B19: 2 | C19: 457 | D19: 7926
B20: 3 | C20: 344 | D20: 7705
B21: 4 | C21: 332 | D21: 8126
B22: 5 | C22: 552 | D22: 8543
B23: 6 | C23: 1225 | D23: 6523
B24: Grand Total | C24: 4921 | D24: 53383
B40: Hours | C40: Casual Customers | D40: Registered Customers
B41: 0 | C41: 74 | D41: 629
B42: 1 | C42: 48 | D42: 412
B43: 2 | C43: 33 | D43: 261
B44: 3 | C44: 34 | D44: 117
B45: 4 | C45: 7 | D45: 62
B46: 5 | C46: 3 | D46: 161
B47: 6 | C47: 21 | D47: 801
B48: 7 | C48: 64 | D48: 2275
B49: 8 | C49: 127 | D49: 5261
B50: 9 | C50: 172 | D50: 3500
B51: 10 | C51: 216 | D51: 2037
B52: 11 | C52: 367 | D52: 2127
... B64: 23 | C64: 101 | D64: 982
B65: Grand Total | C65: 4921 | D65: 53383
G69: Row Labels | H69: Sum of registered Customer
G70: 1 | H70: 34162
G71: 2 | H71: 16568
G72: 3 | H72: 2618
G73: 4 | H73: 35
G74: Grand Total | H74: 53383
B75: Row Labels | C75: Sum of Casual Customer
B76: 1 | C76: 3211
B77: 2 | C77: 1538
B78: 3 | C78: 171
B79: 4 | C79: 1
B80: Grand Total | C80: 4921
H89: Row Labels | I89: Average of atemp
H90: 0 | I90: 0.23390732
...

Sheet dataset_3
A1: Instant | B1: Date | C1: Season | D1: Year | E1: Month | F1: Hour | G1: Holiday | H1: Weekday | I1: Weathersit | J1: Temp | K1: Atemp | L1: Humidity | M1: Windspeed | N1: Casual Customers | O1: Registered Customers | P1: Total Customer
A2: 611 | B2: 40571 | C2: 1 | D2: 0 | E2: 1 | F2: 16 | G2: FALSE | H2: 5 | I2: 1 | J2: 0.22 | K2: 0.2727 | L2: 0.8 | M2: 0 | N2: 10 | O2: 70 | P2: 80
A3: 612 | B3: 40571 | C3: 1 | D3: 0 | E3: 1 | F3: 17 | G3: FALSE | H3: 5 | I3: 1 | J3: 0.24 | K3: 0.2424 | L3: 0.75 | M3: 0.1343 | N3: 2 | O3: 147 | P3: 149
A4: 613 | B4: 40571 | C4: 1 | D4: 0 | E4: 1 | F4: 18 | G4: FALSE | H4: 5 | I4: 1 | J4: 0.24 | K4: 0.2273 | L4: 0.75 | M4: 0.194 | N4: 2 | O4: 107 | P4: 109
A5: 614 | B5: 40571 | C5: 1 | D5: 0 | E5: 1 | F5: 19 | G5: FALSE | H5: 5 | I5: 2 | J5: 0.24 | K5: 0.2424 | L5: 0.75 | M5: 0.1343 | N5: 5 | O5: 84 | P5: 89
A6: 615 | B6: 40571 | C6: 1 | D6: 0 | E6: 1 | F6: 20 | G6: FALSE | H6: 5 | I6: 2 | J6: 0.24 | K6: 0.2273 | L6: 0.7 | M6: 0.194 | N6: 1 | O6: 61 | P6: 62
A7: 616 | B7: 40571 | C7: 1 | D7: 0 | E7: 1 | F7: 21 | G7: FALSE | H7: 5 | I7: 2 | J7: 0.22 | K7: 0.2273 | L7: 0.75 | M7: 0.1343 | N7: 1 | O7: 57 | P7: 58
A8: 617 | B8: 40571 | C8: 1 | D8: 0 | E8: 1 | F8: 22 | G8: FALSE | H8: 5 | I8: 1 | J8: 0.24 | K8: 0.2121 | L8: 0.65 | M8: 0.3582 | N8: 0 | O8: 26 | P8: 26
A9: 618 | B9: 40571 | C9: 1 | D9: 0 | E9: 1 | F9: 23 | G9: FALSE | H9: 5 | I9: 1 | J9: 0.24 | K9: 0.2273 | L9: 0.6 | M9: 0.2239 | N9: 1 | O9: 22 | P9: 23
A10: 619 | B10: 40572 | C10: 1 | D10: 0 | E10: 1 | F10: 0 | G10: FALSE | H10: 6 | I10: 1 | J10: 0.22 | K10: 0.197 | L10: 0.64 | M10: 0.3582 | N10: 2 | O10: 26 | P10: 28
A11: 620 | B11: 40572 | C11: 1 | D11: 0 | E11: 1 | F11: 1 | G11: FALSE | H11: 6 | I11: 1 | J11: 0.22 | K11: 0.2273 | L11: 0.64 | M11: 0.194 | N11: 0 | O11: 20 | P11: 20
A12: 621 | B12: 40572 | C12: 1 | D12: 0 | E12: 1 | F12: 2 | G12: FALSE | H12: 6 | I12: 1 | J12: 0.22 | K12: 0.2273 | L12: 0.64 | M12: 0.1642 | N12: 0 | O12: 15 | P12: 15
A13: 622 | B13: 40572 | C13: 1 | D13: 0 | E13: 1 | F13: 3 | G13: FALSE | H13: 6 | I13: 1 | J13: 0.2 | K13: 0.2121 | L13: 0.64 | M13: 0.1343 | N13: 3 | O13: 5 | P13: 8
... A391: 1000 | B391: 40588 | C391: 1 | D391: 0 | E391: 2 | F391: 7 | G391: FALSE | H391: 1 | I391: 1 | J391: 0.34 | K391: 0.303 | L391: 0.46 | M391: 0.2985 | N391: 2 | O391: 96 | P391: 98
